Workbook

Sheet score_l_equations
B1: Landscape metrics | E1: Buffer Metrics | J1: Vegetation Metrics | Q1: Hydrology Metrics | U1: Physiochemistry | Y1: Size Metrics | AD1: Overall Score
A2: TIA_ID | B2: L1. Contiguous Natural Land Cover | C2: L2. Land Use Index | D2: Total | E2: B1. Perimeter with Natural Buffer | F2: B2. Width of Natural Buffer | G2: B3.1. Condition of Natural Buffer - Veg | H2: B3.2. Condition of Natural Buffer - Soils | I2: Total | J2: V1. Native Plant Species Cover | K2: V2. Invasive Nonnative Plant Species Cover | L2: V3. Native Plant Species Composition | M2: V4. Vegetation Structure | N2: V5. Regen. of Native Woody Species (opt.) | O2: V6. Coarse and Fine Woody Debris (opt.) | P2: Total | Q2: H1. Water Source | R2: H2. Hydroperiod | S2: H3. Hydrologic Connectivity | T2: Total | U2: S1. Soil Condition | V2: S2. Surface Water Turbidity / Pollutants (opt.) | W2: S3. Algal Growth (opt.) | X2: Total | Y2: Z1. Comparative Size (opt.) | Z2: Z2. Change in Size (opt.) | AA2: Total | AB2: Landscape Context score | AC2: Condition Score | AD2: Overall EIA score | AE2: Overall EIA + Size Score
A3: 515 | B3: A | C3: A | D3: =IF(score_n_equations!D3="NULL","NULL",IF(score_n_equations!D3>=4.5,"A",IF(score_n_equations!D3>=3.5,"B",IF(score_n_equations!D3>=2.5,"C",IF(score_n_equations!D3>0,"D"))))) -> A | E3: A | F3: A | G3: B | H3: B | I3: =IF(score_n_equations!I3="NULL","NULL",IF(score_n_equations!I3>=4.5,"A",IF(score_n_equations!I3>=3.5,"B",IF(score_n_equations!I3>=2.5,"C",IF(score_n_equations!I3>0,"D"))))) -> B | J3: C | K3: B | L3: A | M3: A | N3: NA | O3: NA | P3: =IF(score_n_equations!P3="NULL","NULL",IF(score_n_equations!P3>=4.5,"A",IF(score_n_equations!P3>=3.5,"B",IF(score_n_equations!P3>=2.5,"C",IF(score_n_equations!P3>0,"D"))))) -> B | Q3: A | R3: A | S3: A | T3: =IF(score_n_equations!T3="NULL","NULL",IF(score_n_equations!T3>=4.5,"A",IF(score_n_equations!T3>=3.5,"B",IF(score_n_equations!T3>=2.5,"C",IF(score_n_equations!T3>0,"D"))))) -> A | U3: B | V3: A | W3: A | X3: =IF(score_n_equations!X3="NULL","NULL",IF(score_n_equations!X3>=4.5,"A",IF(score_n_equations!X3>=3.5,"B",IF(score_n_equations!X3>=2.5,"C",IF(score_n_equations!X3>0,"D"))))) -> A | Y3: B | Z3: A | AA3: =IF(score_n_equations!AA3="NULL","NULL",IF(score_n_equations!AA3>=4.5,"A",IF(score_n_equations!AA3>=3.5,"B",IF(score_n_equations!AA3>=2.5,"C",IF(score_n_equations!AA3>0,"D"))))) -> A | AB3: =IF(score_n_equations!AB3="NULL","NULL",IF(score_n_equations!AB3>=4.5,"A",IF(score_n_equations!AB3>=3.5,"B",IF(score_n_equations!AB3>=2.5,"C",IF(score_n_equations!AB3>0,"D"))))) -> A | AC3: =IF(score_n_equations!AC3="NULL","NULL",IF(score_n_equations!AC3>=4.5,"A",IF(score_n_equations!AC3>=3.5,"B",IF(score_n_equations!AC3>=2.5,"C",IF(score_n_equations!AC3>0,"D"))))) -> A | AD3: =IF(score_n_equations!AD3="NULL","NULL",IF(score_n_equations!AD3>=4.5,"A",IF(score_n_equations!AD3>=3.5,"B",IF(score_n_equations!AD3>=2.5,"C",IF(score_n_equations!AD3>0,"D"))))) -> A | AE3: =IF(score_n_equations!AE3="NULL","NULL",IF(score_n_equations!AE3>=4.5,"A",IF(score_n_equations!AE3>=3.5,"B",IF(score_n_equations!AE3>=2.5,"C",IF(score_n_equations!AE3>0,"D"))))) -> A
A4: 603 | B4: A | C4: A | D4: =IF(score_n_equations!D4="NULL","NULL",IF(score_n_equations!D4>=4.5,"A",IF(score_n_equations!D4>=3.5,"B",IF(score_n_equations!D4>=2.5,"C",IF(score_n_equations!D4>0,"D"))))) -> A | E4: A | F4: A | G4: B | H4: B | I4: =IF(score_n_equations!I4="NULL","NULL",IF(score_n_equations!I4>=4.5,"A",IF(score_n_equations!I4>=3.5,"B",IF(score_n_equations!I4>=2.5,"C",IF(score_n_equations!I4>0,"D"))))) -> B | J4: C- | K4: B | L4: C | M4: A | N4: NA | O4: NA | P4: =IF(score_n_equations!P4="NULL","NULL",IF(score_n_equations!P4>=4.5,"A",IF(score_n_equations!P4>=3.5,"B",IF(score_n_equations!P4>=2.5,"C",IF(score_n_equations!P4>0,"D"))))) -> B | Q4: A | R4: A | S4: B | T4: =IF(score_n_equations!T4="NULL","NULL",IF(score_n_equations!T4>=4.5,"A",IF(score_n_equations!T4>=3.5,"B",IF(score_n_equations!T4>=2.5,"C",IF(score_n_equations!T4>0,"D"))))) -> A | U4: C | V4: NA | W4: NA | X4: =IF(score_n_equations!X4="NULL","NULL",IF(score_n_equations!X4>=4.5,"A",IF(score_n_equations!X4>=3.5,"B",IF(score_n_equations!X4>=2.5,"C",IF(score_n_equations!X4>0,"D"))))) -> C | Y4: C | Z4: A | AA4: =IF(score_n_equations!AA4="NULL","NULL",IF(score_n_equations!AA4>=4.5,"A",IF(score_n_equations!AA4>=3.5,"B",IF(score_n_equations!AA4>=2.5,"C",IF(score_n_equations!AA4>0,"D"))))) -> B | AB4: =IF(score_n_equations!AB4="NULL","NULL",IF(score_n_equations!AB4>=4.5,"A",IF(score_n_equations!AB4>=3.5,"B",IF(score_n_equations!AB4>=2.5,"C",IF(score_n_equations!AB4>0,"D"))))) -> A | AC4: =IF(score_n_equations!AC4="NULL","NULL",IF(score_n_equations!AC4>=4.5,"A",IF(score_n_equations!AC4>=3.5,"B",IF(score_n_equations!AC4>=2.5,"C",IF(score_n_equations!AC4>0,"D"))))) -> B | AD4: =IF(score_n_equations!AD4="NULL","NULL",IF(score_n_equations!AD4>=4.5,"A",IF(score_n_equations!AD4>=3.5,"B",IF(score_n_equations!AD4>=2.5,"C",IF(score_n_equations!AD4>0,"D"))))) -> B | AE4: =IF(score_n_equations!AE4="NULL","NULL",IF(score_n_equations!AE4>=4.5,"A",IF(score_n_equations!AE4>=3.5,"B",IF(score_n_equations!AE4>=2.5,"C",IF(score_n_equations!AE4>0,"D"))))) -> A
A5: 667 | B5: D | C5: D | D5: =IF(score_n_equations!D5="NULL","NULL",IF(score_n_equations!D5>=4.5,"A",IF(score_n_equations!D5>=3.5,"B",IF(score_n_equations!D5>=2.5,"C",IF(score_n_equations!D5>0,"D"))))) -> D | E5: C | F5: C | G5: C | H5: C | I5: =IF(score_n_equations!I5="NULL","NULL",IF(score_n_equations!I5>=4.5,"A",IF(score_n_equations!I5>=3.5,"B",IF(score_n_equations!I5>=2.5,"C",IF(score_n_equations!I5>0,"D"))))) -> C | J5: D | K5: C | L5: C | M5: B | N5: B | O5: C | P5: =IF(score_n_equations!P5="NULL","NULL",IF(score_n_equations!P5>=4.5,"A",IF(score_n_equations!P5>=3.5,"B",IF(score_n_equations!P5>=2.5,"C",IF(score_n_equations!P5>0,"D"))))) -> C | Q5: B | R5: D | S5: C | T5: =IF(score_n_equations!T5="NULL","NULL",IF(score_n_equations!T5>=4.5,"A",IF(score_n_equations!T5>=3.5,"B",IF(score_n_equations!T5>=2.5,"C",IF(score_n_equations!T5>0,"D"))))) -> C | U5: B | V5: D | W5: A | X5: =IF(score_n_equations!X5="NULL","NULL",IF(score_n_equations!X5>=4.5,"A",IF(score_n_equations!X5>=3.5,"B",IF(score_n_equations!X5>=2.5,"C",IF(score_n_equations!X5>0,"D"))))) -> C | Y5: C | Z5: D | AA5: =IF(score_n_equations!AA5="NULL","NULL",IF(score_n_equations!AA5>=4.5,"A",IF(score_n_equations!AA5>=3.5,"B",IF(score_n_equations!AA5>=2.5,"C",IF(score_n_equations!AA5>0,"D"))))) -> D | AB5: =IF(score_n_equations!AB5="NULL","NULL",IF(score_n_equations!AB5>=4.5,"A",IF(score_n_equations!AB5>=3.5,"B",IF(score_n_equations!AB5>=2.5,"C",IF(score_n_equations!AB5>0,"D"))))) -> D | AC5: =IF(score_n_equations!AC5="NULL","NULL",IF(score_n_equations!AC5>=4.5,"A",IF(score_n_equations!AC5>=3.5,"B",IF(score_n_equations!AC5>=2.5,"C",IF(score_n_equations!AC5>0,"D"))))) -> C | AD5: =IF(score_n_equations!AD5="NULL","NULL",IF(score_n_equations!AD5>=4.5,"A",IF(score_n_equations!AD5>=3.5,"B",IF(score_n_equations!AD5>=2.5,"C",IF(score_n_equations!AD5>0,"D"))))) -> C | AE5: =IF(score_n_equations!AE5="NULL","NULL",IF(score_n_equations!AE5>=4.5,"A",IF(score_n_equations!AE5>=3.5,"B",IF(score_n_equations!AE5>=2.5,"C",IF(score_n_equations!AE5>0,"D"))))) -> D
A6: 674 | B6: A | C6: A | D6: =IF(score_n_equations!D6="NULL","NULL",IF(score_n_equations!D6>=4.5,"A",IF(score_n_equations!D6>=3.5,"B",IF(score_n_equations!D6>=2.5,"C",IF(score_n_equations!D6>0,"D"))))) -> A | E6: A | F6: A | G6: B | H6: A | I6: =IF(score_n_equations!I6="NULL","NULL",IF(score_n_equations!I6>=4.5,"A",IF(score_n_equations!I6>=3.5,"B",IF(score_n_equations!I6>=2.5,"C",IF(score_n_equations!I6>0,"D"))))) -> A | J6: C | K6: B | L6: B | M6: A | N6: NA | O6: NA | P6: =IF(score_n_equations!P6="NULL","NULL",IF(score_n_equations!P6>=4.5,"A",IF(score_n_equations!P6>=3.5,"B",IF(score_n_equations!P6>=2.5,"C",IF(score_n_equations!P6>0,"D"))))) -> B | Q6: A | R6: A | S6: A | T6: =IF(score_n_equations!T6="NULL","NULL",IF(score_n_equations!T6>=4.5,"A",IF(score_n_equations!T6>=3.5,"B",IF(score_n_equations!T6>=2.5,"C",IF(score_n_equations!T6>0,"D"))))) -> A | U6: B | V6: A | W6: A | X6: =IF(score_n_equations!X6="NULL","NULL",IF(score_n_equations!X6>=4.5,"A",IF(score_n_equations!X6>=3.5,"B",IF(score_n_equations!X6>=2.5,"C",IF(score_n_equations!X6>0,"D"))))) -> A | Y6: B | Z6: A | AA6: =IF(score_n_equations!AA6="NULL","NULL",IF(score_n_equations!AA6>=4.5,"A",IF(score_n_equations!AA6>=3.5,"B",IF(score_n_equations!AA6>=2.5,"C",IF(score_n_equations!AA6>0,"D"))))) -> A | AB6: =IF(score_n_equations!AB6="NULL","NULL",IF(score_n_equations!AB6>=4.5,"A",IF(score_n_equations!AB6>=3.5,"B",IF(score_n_equations!AB6>=2.5,"C",IF(score_n_equations!AB6>0,"D"))))) -> A | AC6: =IF(score_n_equations!AC6="NULL","NULL",IF(score_n_equations!AC6>=4.5,"A",IF(score_n_equations!AC6>=3.5,"B",IF(score_n_equations!AC6>=2.5,"C",IF(score_n_equations!AC6>0,"D"))))) -> B | AD6: =IF(score_n_equations!AD6="NULL","NULL",IF(score_n_equations!AD6>=4.5,"A",IF(score_n_equations!AD6>=3.5,"B",IF(score_n_equations!AD6>=2.5,"C",IF(score_n_equations!AD6>0,"D"))))) -> A | AE6: =IF(score_n_equations!AE6="NULL","NULL",IF(score_n_equations!AE6>=4.5,"A",IF(score_n_equations!AE6>=3.5,"B",IF(score_n_equations!AE6>=2.5,"C",IF(score_n_equations!AE6>0,"D"))))) -> A
A7: 1102 | B7: B | C7: A | D7: =IF(score_n_equations!D7="NULL","NULL",IF(score_n_equations!D7>=4.5,"A",IF(score_n_equations!D7>=3.5,"B",IF(score_n_equations!D7>=2.5,"C",IF(score_n_equations!D7>0,"D"))))) -> A | E7: B | F7: B | G7: A | H7: A | I7: =IF(score_n_equations!I7="NULL","NULL",IF(score_n_equations!I7>=4.5,"A",IF(score_n_equations!I7>=3.5,"B",IF(score_n_equations!I7>=2.5,"C",IF(score_n_equations!I7>0,"D"))))) -> B | J7: C | K7: A | L7: A | M7: A | N7: NA | O7: NA | P7: =IF(score_n_equations!P7="NULL","NULL",IF(score_n_equations!P7>=4.5,"A",IF(score_n_equations!P7>=3.5,"B",IF(score_n_equations!P7>=2.5,"C",IF(score_n_equations!P7>0,"D"))))) -> A | Q7: A | R7: A | S7: A | T7: =IF(score_n_equations!T7="NULL","NULL",IF(score_n_equations!T7>=4.5,"A",IF(score_n_equations!T7>=3.5,"B",IF(score_n_equations!T7>=2.5,"C",IF(score_n_equations!T7>0,"D"))))) -> A | U7: A | V7: A | W7: A | X7: =IF(score_n_equations!X7="NULL","NULL",IF(score_n_equations!X7>=4.5,"A",IF(score_n_equations!X7>=3.5,"B",IF(score_n_equations!X7>=2.5,"C",IF(score_n_equations!X7>0,"D"))))) -> A | Y7: A | Z7: C | AA7: =IF(score_n_equations!AA7="NULL","NULL",IF(score_n_equations!AA7>=4.5,"A",IF(score_n_equations!AA7>=3.5,"B",IF(score_n_equations!AA7>=2.5,"C",IF(score_n_equations!AA7>0,"D"))))) -> B | AB7: =IF(score_n_equations!AB7="NULL","NULL",IF(score_n_equations!AB7>=4.5,"A",IF(score_n_equations!AB7>=3.5,"B",IF(score_n_equations!AB7>=2.5,"C",IF(score_n_equations!AB7>0,"D"))))) -> B | AC7: =IF(score_n_equations!AC7="NULL","NULL",IF(score_n_equations!AC7>=4.5,"A",IF(score_n_equations!AC7>=3.5,"B",IF(score_n_equations!AC7>=2.5,"C",IF(score_n_equations!AC7>0,"D"))))) -> A | AD7: =IF(score_n_equations!AD7="NULL","NULL",IF(score_n_equations!AD7>=4.5,"A",IF(score_n_equations!AD7>=3.5,"B",IF(score_n_equations!AD7>=2.5,"C",IF(score_n_equations!AD7>0,"D"))))) -> A | AE7: =IF(score_n_equations!AE7="NULL","NULL",IF(score_n_equations!AE7>=4.5,"A",IF(score_n_equations!AE7>=3.5,"B",IF(score_n_equations!AE7>=2.5,"C",IF(score_n_equations!AE7>0,"D"))))) -> A
A8: 1251 | B8: A | C8: A | D8: =IF(score_n_equations!D8="NULL","NULL",IF(score_n_equations!D8>=4.5,"A",IF(score_n_equations!D8>=3.5,"B",IF(score_n_equations!D8>=2.5,"C",IF(score_n_equations!D8>0,"D"))))) -> A | E8: A | F8: A | G8: A | H8: A | I8: =IF(score_n_equations!I8="NULL","NULL",IF(score_n_equations!I8>=4.5,"A",IF(score_n_equations!I8>=3.5,"B",IF(score_n_equations!I8>=2.5,"C",IF(score_n_equations!I8>0,"D"))))) -> A | J8: C | K8: C | L8: C | M8: C | N8: NA | O8: NA | P8: =IF(score_n_equations!P8="NULL","NULL",IF(score_n_equations!P8>=4.5,"A",IF(score_n_equations!P8>=3.5,"B",IF(score_n_equations!P8>=2.5,"C",IF(score_n_equations!P8>0,"D"))))) -> C | Q8: A | R8: A | S8: B | T8: =IF(score_n_equations!T8="NULL","NULL",IF(score_n_equations!T8>=4.5,"A",IF(score_n_equations!T8>=3.5,"B",IF(score_n_equations!T8>=2.5,"C",IF(score_n_equations!T8>0,"D"))))) -> A | U8: C | V8: A | W8: C | X8: =IF(score_n_equations!X8="NULL","NULL",IF(score_n_equations!X8>=4.5,"A",IF(score_n_equations!X8>=3.5,"B",IF(score_n_equations!X8>=2.5,"C",IF(score_n_equations!X8>0,"D"))))) -> B | Y8: B | Z8: A | AA8: =IF(score_n_equations!AA8="NULL","NULL",IF(score_n_equations!AA8>=4.5,"A",IF(score_n_equations!AA8>=3.5,"B",IF(score_n_equations!AA8>=2.5,"C",IF(score_n_equations!AA8>0,"D"))))) -> A | AB8: =IF(score_n_equations!AB8="NULL","NULL",IF(score_n_equations!AB8>=4.5,"A",IF(score_n_equations!AB8>=3.5,"B",IF(score_n_equations!AB8>=2.5,"C",IF(score_n_equations!AB8>0,"D"))))) -> A | AC8: =IF(score_n_equations!AC8="NULL","NULL",IF(score_n_equations!AC8>=4.5,"A",IF(score_n_equations!AC8>=3.5,"B",IF(score_n_equations!AC8>=2.5,"C",IF(score_n_equations!AC8>0,"D"))))) -> B | AD8: =IF(score_n_equations!AD8="NULL","NULL",IF(score_n_equations!AD8>=4.5,"A",IF(score_n_equations!AD8>=3.5,"B",IF(score_n_equations!AD8>=2.5,"C",IF(score_n_equations!AD8>0,"D"))))) -> B | AE8: =IF(score_n_equations!AE8="NULL","NULL",IF(score_n_equations!AE8>=4.5,"A",IF(score_n_equations!AE8>=3.5,"B",IF(score_n_equations!AE8>=2.5,"C",IF(score_n_equations!AE8>0,"D"))))) -> A
A9: 1270 | B9: B | C9: A | D9: =IF(score_n_equations!D9="NULL","NULL",IF(score_n_equations!D9>=4.5,"A",IF(score_n_equations!D9>=3.5,"B",IF(score_n_equations!D9>=2.5,"C",IF(score_n_equations!D9>0,"D"))))) -> A | E9: A | F9: A | G9: C | H9: B | I9: =IF(score_n_equations!I9="NULL","NULL",IF(score_n_equations!I9>=4.5,"A",IF(score_n_equations!I9>=3.5,"B",IF(score_n_equations!I9>=2.5,"C",IF(score_n_equations!I9>0,"D"))))) -> B | J9: C- | K9: B | L9: C | M9: C | N9: NA | O9: NA | P9: =IF(score_n_equations!P9="NULL","NULL",IF(score_n_equations!P9>=4.5,"A",IF(score_n_equations!P9>=3.5,"B",IF(score_n_equations!P9>=2.5,"C",IF(score_n_equations!P9>0,"D"))))) -> C | Q9: A | R9: A | S9: A | T9: =IF(score_n_equations!T9="NULL","NULL",IF(score_n_equations!T9>=4.5,"A",IF(score_n_equations!T9>=3.5,"B",IF(score_n_equations!T9>=2.5,"C",IF(score_n_equations!T9>0,"D"))))) -> A | U9: A | V9: A | W9: C | X9: =IF(score_n_equations!X9="NULL","NULL",IF(score_n_equations!X9>=4.5,"A",IF(score_n_equations!X9>=3.5,"B",IF(score_n_equations!X9>=2.5,"C",IF(score_n_equations!X9>0,"D"))))) -> B | Y9: A | Z9: A | AA9: =IF(score_n_equations!AA9="NULL","NULL",IF(score_n_equations!AA9>=4.5,"A",IF(score_n_equations!AA9>=3.5,"B",IF(score_n_equations!AA9>=2.5,"C",IF(score_n_equations!AA9>0,"D"))))) -> A | AB9: =IF(score_n_equations!AB9="NULL","NULL",IF(score_n_equations!AB9>=4.5,"A",IF(score_n_equations!AB9>=3.5,"B",IF(score_n_equations!AB9>=2.5,"C",IF(score_n_equations!AB9>0,"D"))))) -> B | AC9: =IF(score_n_equations!AC9="NULL","NULL",IF(score_n_equations!AC9>=4.5,"A",IF(score_n_equations!AC9>=3.5,"B",IF(score_n_equations!AC9>=2.5,"C",IF(score_n_equations!AC9>0,"D"))))) -> B | AD9: =IF(score_n_equations!AD9="NULL","NULL",IF(score_n_equations!AD9>=4.5,"A",IF(score_n_equations!AD9>=3.5,"B",IF(score_n_equations!AD9>=2.5,"C",IF(score_n_equations!AD9>0,"D"))))) -> B | AE9: =IF(score_n_equations!AE9="NULL","NULL",IF(score_n_equations!AE9>=4.5,"A",IF(score_n_equations!AE9>=3.5,"B",IF(score_n_equations!AE9>=2.5,"C",IF(score_n_equations!AE9>0,"D"))))) -> B
A10: 1368 | B10: A | C10: A | D10: =IF(score_n_equations!D10="NULL","NULL",IF(score_n_equations!D10>=4.5,"A",IF(score_n_equations!D10>=3.5,"B",IF(score_n_equations!D10>=2.5,"C",IF(score_n_equations!D10>0,"D"))))) -> A | E10: A | F10: A | G10: B | H10: B | I10: =IF(score_n_equations!I10="NULL","NULL",IF(score_n_equations!I10>=4.5,"A",IF(score_n_equations!I10>=3.5,"B",IF(score_n_equations!I10>=2.5,"C",IF(score_n_equations!I10>0,"D"))))) -> B | J10: B | K10: B | L10: A | M10: A | N10: NA | O10: NA | P10: =IF(score_n_equations!P10="NULL","NULL",IF(score_n_equations!P10>=4.5,"A",IF(score_n_equations!P10>=3.5,"B",IF(score_n_equations!P10>=2.5,"C",IF(score_n_equations!P10>0,"D"))))) -> A | Q10: A | R10: B | S10: B | T10: =IF(score_n_equations!T10="NULL","NULL",IF(score_n_equations!T10>=4.5,"A",IF(score_n_equations!T10>=3.5,"B",IF(score_n_equations!T10>=2.5,"C",IF(score_n_equations!T10>0,"D"))))) -> B | U10: C | V10: A | W10: A | X10: =IF(score_n_equations!X10="NULL","NULL",IF(score_n_equations!X10>=4.5,"A",IF(score_n_equations!X10>=3.5,"B",IF(score_n_equations!X10>=2.5,"C",IF(score_n_equations!X10>0,"D"))))) -> B | Y10: A | Z10: A | AA10: =IF(score_n_equations!AA10="NULL","NULL",IF(score_n_equations!AA10>=4.5,"A",IF(score_n_equations!AA10>=3.5,"B",IF(score_n_equations!AA10>=2.5,"C",IF(score_n_equations!AA10>0,"D"))))) -> A | AB10: =IF(score_n_equations!AB10="NULL","NULL",IF(score_n_equations!AB10>=4.5,"A",IF(score_n_equations!AB10>=3.5,"B",IF(score_n_equations!AB10>=2.5,"C",IF(score_n_equations!AB10>0,"D"))))) -> A | AC10: =IF(score_n_equations!AC10="NULL","NULL",IF(score_n_equations!AC10>=4.5,"A",IF(score_n_equations!AC10>=3.5,"B",IF(score_n_equations!AC10>=2.5,"C",IF(score_n_equations!AC10>0,"D"))))) -> B | AD10: =IF(score_n_equations!AD10="NULL","NULL",IF(score_n_equations!AD10>=4.5,"A",IF(score_n_equations!AD10>=3.5,"B",IF(score_n_equations!AD10>=2.5,"C",IF(score_n_equations!AD10>0,"D"))))) -> B | AE10: =IF(score_n_equations!AE10="NULL","NULL",IF(score_n_equations!AE10>=4.5,"A",IF(score_n_equations!AE10>=3.5,"B",IF(score_n_equations!AE10>=2.5,"C",IF(score_n_equations!AE10>0,"D"))))) -> A
A11: 1610 | B11: C | C11: B | D11: =IF(score_n_equations!D11="NULL","NULL",IF(score_n_equations!D11>=4.5,"A",IF(score_n_equations!D11>=3.5,"B",IF(score_n_equations!D11>=2.5,"C",IF(score_n_equations!D11>0,"D"))))) -> B | E11: B | F11: B | G11: B | H11: C | I11: =IF(score_n_equations!I11="NULL","NULL",IF(score_n_equations!I11>=4.5,"A",IF(score_n_equations!I11>=3.5,"B",IF(score_n_equations!I11>=2.5,"C",IF(score_n_equations!I11>0,"D"))))) -> B | J11: B | K11: B | L11: A | M11: A | N11: NA | O11: NA | P11: =IF(score_n_equations!P11="NULL","NULL",IF(score_n_equations!P11>=4.5,"A",IF(score_n_equations!P11>=3.5,"B",IF(score_n_equations!P11>=2.5,"C",IF(score_n_equations!P11>0,"D"))))) -> A | Q11: A | R11: A | S11: B | T11: =IF(score_n_equations!T11="NULL","NULL",IF(score_n_equations!T11>=4.5,"A",IF(score_n_equations!T11>=3.5,"B",IF(score_n_equations!T11>=2.5,"C",IF(score_n_equations!T11>0,"D"))))) -> A | U11: C | V11: A | W11: B | X11: =IF(score_n_equations!X11="NULL","NULL",IF(score_n_equations!X11>=4.5,"A",IF(score_n_equations!X11>=3.5,"B",IF(score_n_equations!X11>=2.5,"C",IF(score_n_equations!X11>0,"D"))))) -> B | Y11: A | Z11: A | AA11: =IF(score_n_equations!AA11="NULL","NULL",IF(score_n_equations!AA11>=4.5,"A",IF(score_n_equations!AA11>=3.5,"B",IF(score_n_equations!AA11>=2.5,"C",IF(score_n_equations!AA11>0,"D"))))) -> A | AB11: =IF(score_n_equations!AB11="NULL","NULL",IF(score_n_equations!AB11>=4.5,"A",IF(score_n_equations!AB11>=3.5,"B",IF(score_n_equations!AB11>=2.5,"C",IF(score_n_equations!AB11>0,"D"))))) -> B | AC11: =IF(score_n_equations!AC11="NULL","NULL",IF(score_n_equations!AC11>=4.5,"A",IF(score_n_equations!AC11>=3.5,"B",IF(score_n_equations!AC11>=2.5,"C",IF(score_n_equations!AC11>0,"D"))))) -> A | AD11: =IF(score_n_equations!AD11="NULL","NULL",IF(score_n_equations!AD11>=4.5,"A",IF(score_n_equations!AD11>=3.5,"B",IF(score_n_equations!AD11>=2.5,"C",IF(score_n_equations!AD11>0,"D"))))) -> B | AE11: =IF(score_n_equations!AE11="NULL","NULL",IF(score_n_equations!AE11>=4.5,"A",IF(score_n_equations!AE11>=3.5,"B",IF(score_n_equations!AE11>=2.5,"C",IF(score_n_equations!AE11>0,"D"))))) -> A
A12: 1611 | B12: C | C12: C | D12: =IF(score_n_equations!D12="NULL","NULL",IF(score_n_equations!D12>=4.5,"A",IF(score_n_equations!D12>=3.5,"B",IF(score_n_equations!D12>=2.5,"C",IF(score_n_equations!D12>0,"D"))))) -> C | E12: A | F12: B | G12: D | H12: A | I12: =IF(score_n_equations!I12="NULL","NULL",IF(score_n_equations!I12>=4.5,"A",IF(score_n_equations!I12>=3.5,"B",IF(score_n_equations!I12>=2.5,"C",IF(score_n_equations!I12>0,"D"))))) -> B | J12: C- | K12: C- | L12: B | M12: A | N12: NA | O12: NA | P12: =IF(score_n_equations!P12="NULL","NULL",IF(score_n_equations!P12>=4.5,"A",IF(score_n_equations!P12>=3.5,"B",IF(score_n_equations!P12>=2.5,"C",IF(score_n_equations!P12>0,"D"))))) -> C | Q12: B | R12: A | S12: A | T12: =IF(score_n_equations!T12="NULL","NULL",IF(score_n_equations!T12>=4.5,"A",IF(score_n_equations!T12>=3.5,"B",IF(score_n_equations!T12>=2.5,"C",IF(score_n_equations!T12>0,"D"))))) -> A | U12: B | V12: NA | W12: NA | X12: =IF(score_n_equations!X12="NULL","NULL",IF(score_n_equations!X12>=4.5,"A",IF(score_n_equations!X12>=3.5,"B",IF(score_n_equations!X12>=2.5,"C",IF(score_n_equations!X12>0,"D"))))) -> B | Y12: B | Z12: A | AA12: =IF(score_n_equations!AA12="NULL","NULL",IF(score_n_equations!AA12>=4.5,"A",IF(score_n_equations!AA12>=3.5,"B",IF(score_n_equations!AA12>=2.5,"C",IF(score_n_equations!AA12>0,"D"))))) -> A | AB12: =IF(score_n_equations!AB12="NULL","NULL",IF(score_n_equations!AB12>=4.5,"A",IF(score_n_equations!AB12>=3.5,"B",IF(score_n_equations!AB12>=2.5,"C",IF(score_n_equations!AB12>0,"D"))))) -> C | AC12: =IF(score_n_equations!AC12="NULL","NULL",IF(score_n_equations!AC12>=4.5,"A",IF(score_n_equations!AC12>=3.5,"B",IF(score_n_equations!AC12>=2.5,"C",IF(score_n_equations!AC12>0,"D"))))) -> B | AD12: =IF(score_n_equations!AD12="NULL","NULL",IF(score_n_equations!AD12>=4.5,"A",IF(score_n_equations!AD12>=3.5,"B",IF(score_n_equations!AD12>=2.5,"C",IF(score_n_equations!AD12>0,"D"))))) -> B | AE12: =IF(score_n_equations!AE12="NULL","NULL",IF(score_n_equations!AE12>=4.5,"A",IF(score_n_equations!AE12>=3.5,"B",IF(score_n_equations!AE12>=2.5,"C",IF(score_n_equations!AE12>0,"D"))))) -> B
A13: 1617 | B13: C | C13: C | D13: =IF(score_n_equations!D13="NULL","NULL",IF(score_n_equations!D13>=4.5,"A",IF(score_n_equations!D13>=3.5,"B",IF(score_n_equations!D13>=2.5,"C",IF(score_n_equations!D13>0,"D"))))) -> C | E13: A | F13: B | G13: D | H13: A | I13: =IF(score_n_equations!I13="NULL","NULL",IF(score_n_equations!I13>=4.5,"A",IF(score_n_equations!I13>=3.5,"B",IF(score_n_equations!I13>=2.5,"C",IF(score_n_equations!I13>0,"D"))))) -> B | J13: D | K13: C- | L13: D | M13: C | N13: C | O13: C | P13: =IF(score_n_equations!P13="NULL","NULL",IF(score_n_equations!P13>=4.5,"A",IF(score_n_equations!P13>=3.5,"B",IF(score_n_equations!P13>=2.5,"C",IF(score_n_equations!P13>0,"D"))))) -> D | Q13: D | R13: B | S13: D | T13: =IF(score_n_equations!T13="NULL","NULL",IF(score_n_equations!T13>=4.5,"A",IF(score_n_equations!T13>=3.5,"B",IF(score_n_equations!T13>=2.5,"C",IF(score_n_equations!T13>0,"D"))))) -> D | U13: B | V13: A | W13: B | X13: =IF(score_n_equations!X13="NULL","NULL",IF(score_n_equations!X13>=4.5,"A",IF(score_n_equations!X13>=3.5,"B",IF(score_n_equations!X13>=2.5,"C",IF(score_n_equations!X13>0,"D"))))) -> B | Y13: D | Z13: B | AA13: =IF(score_n_equations!AA13="NULL","NULL",IF(score_n_equations!AA13>=4.5,"A",IF(score_n_equations!AA13>=3.5,"B",IF(score_n_equations!AA13>=2.5,"C",IF(score_n_equations!AA13>0,"D"))))) -> C | AB13: =IF(score_n_equations!AB13="NULL","NULL",IF(score_n_equations!AB13>=4.5,"A",IF(score_n_equations!AB13>=3.5,"B",IF(score_n_equations!AB13>=2.5,"C",IF(score_n_equations!AB13>0,"D"))))) -> C | AC13: =IF(score_n_equations!AC13="NULL","NULL",IF(score_n_equations!AC13>=4.5,"A",IF(score_n_equations!AC13>=3.5,"B",IF(score_n_equations!AC13>=2.5,"C",IF(score_n_equations!AC13>0,"D"))))) -> D | AD13: =IF(score_n_equations!AD13="NULL","NULL",IF(score_n_equations!AD13>=4.5,"A",IF(score_n_equations!AD13>=3.5,"B",IF(score_n_equations!AD13>=2.5,"C",IF(score_n_equations!AD13>0,"D"))))) -> C | AE13: =IF(score_n_equations!AE13="NULL","NULL",IF(score_n_equations!AE13>=4.5,"A",IF(score_n_equations!AE13>=3.5,"B",IF(score_n_equations!AE13>=2.5,"C",IF(score_n_equations!AE13>0,"D"))))) -> C
A14: 1682 | B14: C | C14: B | D14: =IF(score_n_equations!D14="NULL","NULL",IF(score_n_equations!D14>=4.5,"A",IF(score_n_equations!D14>=3.5,"B",IF(score_n_equations!D14>=2.5,"C",IF(score_n_equations!D14>0,"D"))))) -> B | E14: A | F14: A | G14: A | H14: B | I14: =IF(score_n_equations!I14="NULL","NULL",IF(score_n_equations!I14>=4.5,"A",IF(score_n_equations!I14>=3.5,"B",IF(score_n_equations!I14>=2.5,"C",IF(score_n_equations!I14>0,"D"))))) -> A | J14: C- | K14: B | L14: B | M14: A | N14: NA | O14: NA | P14: =IF(score_n_equations!P14="NULL","NULL",IF(score_n_equations!P14>=4.5,"A",IF(score_n_equations!P14>=3.5,"B",IF(score_n_equations!P14>=2.5,"C",IF(score_n_equations!P14>0,"D"))))) -> B | Q14: A | R14: A | S14: A | T14: =IF(score_n_equations!T14="NULL","NULL",IF(score_n_equations!T14>=4.5,"A",IF(score_n_equations!T14>=3.5,"B",IF(score_n_equations!T14>=2.5,"C",IF(score_n_equations!T14>0,"D"))))) -> A | U14: A | V14: B | W14: B | X14: =IF(score_n_equations!X14="NULL","NULL",IF(score_n_equations!X14>=4.5,"A",IF(score_n_equations!X14>=3.5,"B",IF(score_n_equations!X14>=2.5,"C",IF(score_n_equations!X14>0,"D"))))) -> B | Y14: A | Z14: A | AA14: =IF(score_n_equations!AA14="NULL","NULL",IF(score_n_equations!AA14>=4.5,"A",IF(score_n_equations!AA14>=3.5,"B",IF(score_n_equations!AA14>=2.5,"C",IF(score_n_equations!AA14>0,"D"))))) -> A | AB14: =IF(score_n_equations!AB14="NULL","NULL",IF(score_n_equations!AB14>=4.5,"A",IF(score_n_equations!AB14>=3.5,"B",IF(score_n_equations!AB14>=2.5,"C",IF(score_n_equations!AB14>0,"D"))))) -> B | AC14: =IF(score_n_equations!AC14="NULL","NULL",IF(score_n_equations!AC14>=4.5,"A",IF(score_n_equations!AC14>=3.5,"B",IF(score_n_equations!AC14>=2.5,"C",IF(score_n_equations!AC14>0,"D"))))) -> B | AD14: =IF(score_n_equations!AD14="NULL","NULL",IF(score_n_equations!AD14>=4.5,"A",IF(score_n_equations!AD14>=3.5,"B",IF(score_n_equations!AD14>=2.5,"C",IF(score_n_equations!AD14>0,"D"))))) -> B | AE14: =IF(score_n_equations!AE14="NULL","NULL",IF(score_n_equations!AE14>=4.5,"A",IF(score_n_equations!AE14>=3.5,"B",IF(score_n_equations!AE14>=2.5,"C",IF(score_n_equations!AE14>0,"D"))))) -> A
... A43: 1966 | B43: C | C43: C | D43: =IF(score_n_equations!D43="NULL","NULL",IF(score_n_equations!D43>=4.5,"A",IF(score_n_equations!D43>=3.5,"B",IF(score_n_equations!D43>=2.5,"C",IF(score_n_equations!D43>0,"D"))))) -> C | E43: B | F43: A | G43: B | H43: B | I43: =IF(score_n_equations!I43="NULL","NULL",IF(score_n_equations!I43>=4.5,"A",IF(score_n_equations!I43>=3.5,"B",IF(score_n_equations!I43>=2.5,"C",IF(score_n_equations!I43>0,"D"))))) -> B | J43: C- | K43: B | L43: C | M43: A | N43: NA | O43: NA | P43: =IF(score_n_equations!P43="NULL","NULL",IF(score_n_equations!P43>=4.5,"A",IF(score_n_equations!P43>=3.5,"B",IF(score_n_equations!P43>=2.5,"C",IF(score_n_equations!P43>0,"D"))))) -> B | Q43: A | R43: B | S43: A | T43: =IF(score_n_equations!T43="NULL","NULL",IF(score_n_equations!T43>=4.5,"A",IF(score_n_equations!T43>=3.5,"B",IF(score_n_equations!T43>=2.5,"C",IF(score_n_equations!T43>0,"D"))))) -> A | U43: C | V43: NA | W43: NA | X43: =IF(score_n_equations!X43="NULL","NULL",IF(score_n_equations!X43>=4.5,"A",IF(score_n_equations!X43>=3.5,"B",IF(score_n_equations!X43>=2.5,"C",IF(score_n_equations!X43>0,"D"))))) -> C | Y43: B | Z43: B | AA43: =IF(score_n_equations!AA43="NULL","NULL",IF(score_n_equations!AA43>=4.5,"A",IF(score_n_equations!AA43>=3.5,"B",IF(score_n_equations!AA43>=2.5,"C",IF(score_n_equations!AA43>0,"D"))))) -> B | AB43: =IF(score_n_equations!AB43="NULL","NULL",IF(score_n_equations!AB43>=4.5,"A",IF(score_n_equations!AB43>=3.5,"B",IF(score_n_equations!AB43>=2.5,"C",IF(score_n_equations!AB43>0,"D"))))) -> B | AC43: =IF(score_n_equations!AC43="NULL","NULL",IF(score_n_equations!AC43>=4.5,"A",IF(score_n_equations!AC43>=3.5,"B",IF(score_n_equations!AC43>=2.5,"C",IF(score_n_equations!AC43>0,"D"))))) -> B | AD43: =IF(score_n_equations!AD43="NULL","NULL",IF(score_n_equations!AD43>=4.5,"A",IF(score_n_equations!AD43>=3.5,"B",IF(score_n_equations!AD43>=2.5,"C",IF(score_n_equations!AD43>0,"D"))))) -> B | AE43: =IF(score_n_equations!AE43="NULL","NULL",IF(score_n_equations!AE43>=4.5,"A",IF(score_n_equations!AE43>=3.5,"B",IF(score_n_equations!AE43>=2.5,"C",IF(score_n_equations!AE43>0,"D"))))) -> B

Sheet score_n_equations
B1: Landscape metrics | E1: Buffer Metrics | J1: Vegetation Metrics | Q1: Hydrology Metrics | U1: Physiochemistry | Y1: Size Metrics | AD1: Overall Score
A2: TIA_ID | B2: L1. Contiguous Natural Land Cover | C2: L2. Land Use Index | D2: Total | E2: B1. Perimeter with Natural Buffer | F2: B2. Width of Natural Buffer | G2: B3.1. Condition of Natural Buffer - Veg | H2: B3.2. Condition of Natural Buffer - Soils | I2: Total | J2: V1. Native Plant Species Cover | K2: V2. Invasive Nonnative Plant Species Cover | L2: V3. Native Plant Species Composition | M2: V4. Vegetation Structure | N2: V5. Regen. of Native Woody Species (opt.) | O2: V6. Coarse and Fine Woody Debris (opt.) | P2: Total | Q2: H1. Water Source | R2: H2. Hydroperiod | S2: H3. Hydrologic Connectivity | T2: Total | U2: S1. Soil Condition | V2: S2. Surface Water Turbidity / Pollutants (opt.) | W2: S3. Algal Growth (opt.) | X2: Total | Y2: Z1. Comparative Size (opt.) | Z2: Z2. Change in Size (opt.) | AA2: Total | AB2: Landscape Context score | AC2: Condition | AD2: Total EIA score | AE2: Overall EIA + Size Score and Rank | AF2: size index
A3: 515 | B3: =IF(score_l_equations!B3="A",5,IF(score_l_equations!B3="B",4,IF(score_l_equations!B3="C",3,IF(score_l_equations!B3="D",1,"NULL")))) -> 5 | C3: =IF(score_l_equations!C3="A",5,IF(score_l_equations!C3="B",4,IF(score_l_equations!C3="C",3,IF(score_l_equations!C3="D",1,"NULL")))) -> 5 | D3: =IF(B3="Null","NULL",AVERAGE(B3:C3)) -> 5 | E3: =IF(score_l_equations!E3="A",5,IF(score_l_equations!E3="B",4,IF(score_l_equations!E3="C",3,IF(score_l_equations!E3="D",1,"NULL")))) -> 5 | F3: =IF(score_l_equations!F3="A",5,IF(score_l_equations!F3="B",4,IF(score_l_equations!F3="C",3,IF(score_l_equations!F3="D",1,"NULL")))) -> 5 | G3: =IF(score_l_equations!G3="A",5,IF(score_l_equations!G3="B",4,IF(score_l_equations!G3="C",3,IF(score_l_equations!G3="D",1,"NULL")))) -> 4 | H3: =IF(score_l_equations!H3="A",5,IF(score_l_equations!H3="B",4,IF(score_l_equations!H3="C",3,IF(score_l_equations!H3="D",1,"NULL")))) -> 4 | I3: =IF(E3="Null","NULL",(SQRT(SQRT(E3*F3)*(AVERAGE(G3:H3))))) -> 4.472136 | J3: =IF(score_l_equations!J3="A",5,IF(score_l_equations!J3="B",4,IF(score_l_equations!J3="C",3,IF(score_l_equations!J3="C-",2,IF(score_l_equations!J3="D",1,"NULL"))))) -> 3 | K3: =IF(score_l_equations!K3="A",5,IF(score_l_equations!K3="B",4,IF(score_l_equations!K3="B",4,IF(score_l_equations!K3="C",3,IF(score_l_equations!K3="C-",2,IF(score_l_equations!K3="D",1,"NULL")))))) -> 4 | L3: =IF(score_l_equations!L3="A",5,IF(score_l_equations!L3="B",4,IF(score_l_equations!L3="B",4,IF(score_l_equations!L3="C",3,IF(score_l_equations!L3="C-",2,IF(score_l_equations!L3="D",1,"NULL")))))) -> 5 | M3: =IF(score_l_equations!M3="A",5,IF(score_l_equations!M3="B",4,IF(score_l_equations!M3="B",4,IF(score_l_equations!M3="C",3,IF(score_l_equations!M3="C-",2,IF(score_l_equations!M3="D",1,"NULL")))))) -> 5 | N3: =IF(score_l_equations!N3="A",5,IF(score_l_equations!N3="B",4,IF(score_l_equations!N3="B",4,IF(score_l_equations!N3="C",3,IF(score_l_equations!N3="C-",2,IF(score_l_equations!N3="D",1,"NULL")))))) -> NULL | O3: =IF(score_l_equations!O3="A",5,IF(score_l_equations!O3="B",4,IF(score_l_equations!O3="B",4,IF(score_l_equations!O3="C",3,IF(score_l_equations!O3="C-",2,IF(score_l_equations!O3="D",1,"NULL")))))) -> NULL | P3: =IF(J3="Null","NULL",AVERAGE(J3:O3)) -> 4.25 | Q3: =IF(score_l_equations!Q3="A",5,IF(score_l_equations!Q3="B",4,IF(score_l_equations!Q3="C",3,IF(score_l_equations!Q3="D",1,"NULL")))) -> 5 | R3: =IF(score_l_equations!R3="A",5,IF(score_l_equations!R3="B",4,IF(score_l_equations!R3="C",3,IF(score_l_equations!R3="D",1,"NULL")))) -> 5 | S3: =IF(score_l_equations!S3="A",5,IF(score_l_equations!S3="B",4,IF(score_l_equations!S3="C",3,IF(score_l_equations!S3="D",1,"NULL")))) -> 5 | T3: =IF(Q3="Null","NULL",AVERAGE(Q3:S3)) -> 5 | U3: =IF(score_l_equations!U3="A",5,IF(score_l_equations!U3="B",4,IF(score_l_equations!U3="C",3,IF(score_l_equations!U3="D",1,"NULL")))) -> 4 | V3: =IF(score_l_equations!V3="A",5,IF(score_l_equations!V3="B",4,IF(score_l_equations!V3="C",3,IF(score_l_equations!V3="D",1,"NULL")))) -> 5 | W3: =IF(score_l_equations!W3="A",5,IF(score_l_equations!W3="B",4,IF(score_l_equations!W3="C",3,IF(score_l_equations!W3="D",1,"NULL")))) -> 5 | X3: =IF(U3="Null","NULL",AVERAGE(U3:W3)) -> 4.6666667 | Y3: =IF(score_l_equations!Y3="A",5,IF(score_l_equations!Y3="B",4,IF(score_l_equations!Y3="C",3,IF(score_l_equations!Y3="D",1,"NULL")))) -> 4 | Z3: =IF(score_l_equations!Z3="A",5,IF(score_l_equations!Z3="B",4,IF(score_l_equations!Z3="C",3,IF(score_l_equations!Z3="D",1,"NULL")))) -> 5 | AA3: =IF(Y3="Null","NULL",AVERAGE(Y3:Z3)) -> 4.5 | AB3: =(D3*0.33)+(I3*0.67) -> 4.6463311 | AC3: =(P3*0.55)+(T3*0.35)+(X3*0.1) -> 4.5541667 | AD3: =(AB3*0.3)+(AC3*0.7) -> 4.581816 | AE3: =AD3+AF3 -> 5.081816 | AF3: =IF(AA3<1.5,-0.5,IF(AA3<2.5,-0.25,IF(AA3<3.5,0.25,0.5))) -> 0.5 | AH3: =SUM(P3,T3,X3)/3 -> 4.6388889
A4: 603 | B4: =IF(score_l_equations!B4="A",5,IF(score_l_equations!B4="B",4,IF(score_l_equations!B4="C",3,IF(score_l_equations!B4="D",1,"NULL")))) -> 5 | C4: =IF(score_l_equations!C4="A",5,IF(score_l_equations!C4="B",4,IF(score_l_equations!C4="C",3,IF(score_l_equations!C4="D",1,"NULL")))) -> 5 | D4: =IF(B4="Null","NULL",AVERAGE(B4:C4)) -> 5 | E4: =IF(score_l_equations!E4="A",5,IF(score_l_equations!E4="B",4,IF(score_l_equations!E4="C",3,IF(score_l_equations!E4="D",1,"NULL")))) -> 5 | F4: =IF(score_l_equations!F4="A",5,IF(score_l_equations!F4="B",4,IF(score_l_equations!F4="C",3,IF(score_l_equations!F4="D",1,"NULL")))) -> 5 | G4: =IF(score_l_equations!G4="A",5,IF(score_l_equations!G4="B",4,IF(score_l_equations!G4="C",3,IF(score_l_equations!G4="D",1,"NULL")))) -> 4 | H4: =IF(score_l_equations!H4="A",5,IF(score_l_equations!H4="B",4,IF(score_l_equations!H4="C",3,IF(score_l_equations!H4="D",1,"NULL")))) -> 4 | I4: =IF(E4="Null","NULL",(SQRT(SQRT(E4*F4)*(AVERAGE(G4:H4))))) -> 4.472136 | J4: =IF(score_l_equations!J4="A",5,IF(score_l_equations!J4="B",4,IF(score_l_equations!J4="B",4,IF(score_l_equations!J4="C",3,IF(score_l_equations!J4="C-",2,IF(score_l_equations!J4="D",1,"NULL")))))) -> 2 | K4: =IF(score_l_equations!K4="A",5,IF(score_l_equations!K4="B",4,IF(score_l_equations!K4="B",4,IF(score_l_equations!K4="C",3,IF(score_l_equations!K4="C-",2,IF(score_l_equations!K4="D",1,"NULL")))))) -> 4 | L4: =IF(score_l_equations!L4="A",5,IF(score_l_equations!L4="B",4,IF(score_l_equations!L4="B",4,IF(score_l_equations!L4="C",3,IF(score_l_equations!L4="C-",2,IF(score_l_equations!L4="D",1,"NULL")))))) -> 3 | M4: =IF(score_l_equations!M4="A",5,IF(score_l_equations!M4="B",4,IF(score_l_equations!M4="B",4,IF(score_l_equations!M4="C",3,IF(score_l_equations!M4="C-",2,IF(score_l_equations!M4="D",1,"NULL")))))) -> 5 | N4: =IF(score_l_equations!N4="A",5,IF(score_l_equations!N4="B",4,IF(score_l_equations!N4="B",4,IF(score_l_equations!N4="C",3,IF(score_l_equations!N4="C-",2,IF(score_l_equations!N4="D",1,"NULL")))))) -> NULL | O4: =IF(score_l_equations!O4="A",5,IF(score_l_equations!O4="B",4,IF(score_l_equations!O4="B",4,IF(score_l_equations!O4="C",3,IF(score_l_equations!O4="C-",2,IF(score_l_equations!O4="D",1,"NULL")))))) -> NULL | P4: =IF(J4="Null","NULL",AVERAGE(J4:O4)) -> 3.5 | Q4: =IF(score_l_equations!Q4="A",5,IF(score_l_equations!Q4="B",4,IF(score_l_equations!Q4="C",3,IF(score_l_equations!Q4="D",1,"NULL")))) -> 5 | R4: =IF(score_l_equations!R4="A",5,IF(score_l_equations!R4="B",4,IF(score_l_equations!R4="C",3,IF(score_l_equations!R4="D",1,"NULL")))) -> 5 | S4: =IF(score_l_equations!S4="A",5,IF(score_l_equations!S4="B",4,IF(score_l_equations!S4="C",3,IF(score_l_equations!S4="D",1,"NULL")))) -> 4 | T4: =IF(Q4="Null","NULL",AVERAGE(Q4:S4)) -> 4.6666667 | U4: =IF(score_l_equations!U4="A",5,IF(score_l_equations!U4="B",4,IF(score_l_equations!U4="C",3,IF(score_l_equations!U4="D",1,"NULL")))) -> 3 | V4: =IF(score_l_equations!V4="A",5,IF(score_l_equations!V4="B",4,IF(score_l_equations!V4="C",3,IF(score_l_equations!V4="D",1,"NULL")))) -> NULL | W4: =IF(score_l_equations!W4="A",5,IF(score_l_equations!W4="B",4,IF(score_l_equations!W4="C",3,IF(score_l_equations!W4="D",1,"NULL")))) -> NULL | X4: =IF(U4="Null","NULL",AVERAGE(U4:W4)) -> 3 | Y4: =IF(score_l_equations!Y4="A",5,IF(score_l_equations!Y4="B",4,IF(score_l_equations!Y4="C",3,IF(score_l_equations!Y4="D",1,"NULL")))) -> 3 | Z4: =IF(score_l_equations!Z4="A",5,IF(score_l_equations!Z4="B",4,IF(score_l_equations!Z4="C",3,IF(score_l_equations!Z4="D",1,"NULL")))) -> 5 | AA4: =IF(Y4="Null","NULL",AVERAGE(Y4:Z4)) -> 4 | AB4: =(D4*0.33)+(I4*0.67) -> 4.6463311 | AC4: =(P4*0.55)+(T4*0.35)+(X4*0.1) -> 3.8583333 | AD4: =(AB4*0.3)+(AC4*0.7) -> 4.0947327 | AE4: =AD4+AF4 -> 4.5947327 | AF4: =IF(AA4<1.5,-0.5,IF(AA4<2.5,-0.25,IF(AA4<3.5,0.25,0.5))) -> 0.5
A5: 667 | B5: =IF(score_l_equations!B5="A",5,IF(score_l_equations!B5="B",4,IF(score_l_equations!B5="C",3,IF(score_l_equations!B5="D",1,"NULL")))) -> 1 | C5: =IF(score_l_equations!C5="A",5,IF(score_l_equations!C5="B",4,IF(score_l_equations!C5="C",3,IF(score_l_equations!C5="D",1,"NULL")))) -> 1 | D5: =IF(B5="Null","NULL",AVERAGE(B5:C5)) -> 1 | E5: =IF(score_l_equations!E5="A",5,IF(score_l_equations!E5="B",4,IF(score_l_equations!E5="C",3,IF(score_l_equations!E5="D",1,"NULL")))) -> 3 | F5: =IF(score_l_equations!F5="A",5,IF(score_l_equations!F5="B",4,IF(score_l_equations!F5="C",3,IF(score_l_equations!F5="D",1,"NULL")))) -> 3 | G5: =IF(score_l_equations!G5="A",5,IF(score_l_equations!G5="B",4,IF(score_l_equations!G5="C",3,IF(score_l_equations!G5="D",1,"NULL")))) -> 3 | H5: =IF(score_l_equations!H5="A",5,IF(score_l_equations!H5="B",4,IF(score_l_equations!H5="C",3,IF(score_l_equations!H5="D",1,"NULL")))) -> 3 | I5: =IF(E5="Null","NULL",(SQRT(SQRT(E5*F5)*(AVERAGE(G5:H5))))) -> 3 | J5: =IF(score_l_equations!J5="A",5,IF(score_l_equations!J5="B",4,IF(score_l_equations!J5="B",4,IF(score_l_equations!J5="C",3,IF(score_l_equations!J5="C-",2,IF(score_l_equations!J5="D",1,"NULL")))))) -> 1 | K5: =IF(score_l_equations!K5="A",5,IF(score_l_equations!K5="B",4,IF(score_l_equations!K5="B",4,IF(score_l_equations!K5="C",3,IF(score_l_equations!K5="C-",2,IF(score_l_equations!K5="D",1,"NULL")))))) -> 3 | L5: =IF(score_l_equations!L5="A",5,IF(score_l_equations!L5="B",4,IF(score_l_equations!L5="B",4,IF(score_l_equations!L5="C",3,IF(score_l_equations!L5="C-",2,IF(score_l_equations!L5="D",1,"NULL")))))) -> 3 | M5: =IF(score_l_equations!M5="A",5,IF(score_l_equations!M5="B",4,IF(score_l_equations!M5="B",4,IF(score_l_equations!M5="C",3,IF(score_l_equations!M5="C-",2,IF(score_l_equations!M5="D",1,"NULL")))))) -> 4 | N5: =IF(score_l_equations!N5="A",5,IF(score_l_equations!N5="B",4,IF(score_l_equations!N5="B",4,IF(score_l_equations!N5="C",3,IF(score_l_equations!N5="C-",2,IF(score_l_equations!N5="D",1,"NULL")))))) -> 4 | O5: =IF(score_l_equations!O5="A",5,IF(score_l_equations!O5="B",4,IF(score_l_equations!O5="B",4,IF(score_l_equations!O5="C",3,IF(score_l_equations!O5="C-",2,IF(score_l_equations!O5="D",1,"NULL")))))) -> 3 | P5: =IF(J5="Null","NULL",AVERAGE(J5:O5)) -> 3 | Q5: =IF(score_l_equations!Q5="A",5,IF(score_l_equations!Q5="B",4,IF(score_l_equations!Q5="C",3,IF(score_l_equations!Q5="D",1,"NULL")))) -> 4 | R5: =IF(score_l_equations!R5="A",5,IF(score_l_equations!R5="B",4,IF(score_l_equations!R5="C",3,IF(score_l_equations!R5="D",1,"NULL")))) -> 1 | S5: =IF(score_l_equations!S5="A",5,IF(score_l_equations!S5="B",4,IF(score_l_equations!S5="C",3,IF(score_l_equations!S5="D",1,"NULL")))) -> 3 | T5: =IF(Q5="Null","NULL",AVERAGE(Q5:S5)) -> 2.6666667 | U5: =IF(score_l_equations!U5="A",5,IF(score_l_equations!U5="B",4,IF(score_l_equations!U5="C",3,IF(score_l_equations!U5="D",1,"NULL")))) -> 4 | V5: =IF(score_l_equations!V5="A",5,IF(score_l_equations!V5="B",4,IF(score_l_equations!V5="C",3,IF(score_l_equations!V5="D",1,"NULL")))) -> 1 | W5: =IF(score_l_equations!W5="A",5,IF(score_l_equations!W5="B",4,IF(score_l_equations!W5="C",3,IF(score_l_equations!W5="D",1,"NULL")))) -> 5 | X5: =IF(U5="Null","NULL",AVERAGE(U5:W5)) -> 3.3333333 | Y5: =IF(score_l_equations!Y5="A",5,IF(score_l_equations!Y5="B",4,IF(score_l_equations!Y5="C",3,IF(score_l_equations!Y5="D",1,"NULL")))) -> 3 | Z5: =IF(score_l_equations!Z5="A",5,IF(score_l_equations!Z5="B",4,IF(score_l_equations!Z5="C",3,IF(score_l_equations!Z5="D",1,"NULL")))) -> 1 | AA5: =IF(Y5="Null","NULL",AVERAGE(Y5:Z5)) -> 2 | AB5: =(D5*0.33)+(I5*0.67) -> 2.34 | AC5: =(P5*0.55)+(T5*0.35)+(X5*0.1) -> 2.9166667 | AD5: =(AB5*0.3)+(AC5*0.7) -> 2.7436667 | AE5: =AD5+AF5 -> 2.4936667 | AF5: =IF(AA5<1.5,-0.5,IF(AA5<2.5,-0.25,IF(AA5<3.5,0.25,0.5))) -> -0.25
A6: 674 | B6: =IF(score_l_equations!B6="A",5,IF(score_l_equations!B6="B",4,IF(score_l_equations!B6="C",3,IF(score_l_equations!B6="D",1,"NULL")))) -> 5 | C6: =IF(score_l_equations!C6="A",5,IF(score_l_equations!C6="B",4,IF(score_l_equations!C6="C",3,IF(score_l_equations!C6="D",1,"NULL")))) -> 5 | D6: =IF(B6="Null","NULL",AVERAGE(B6:C6)) -> 5 | E6: =IF(score_l_equations!E6="A",5,IF(score_l_equations!E6="B",4,IF(score_l_equations!E6="C",3,IF(score_l_equations!E6="D",1,"NULL")))) -> 5 | F6: =IF(score_l_equations!F6="A",5,IF(score_l_equations!F6="B",4,IF(score_l_equations!F6="C",3,IF(score_l_equations!F6="D",1,"NULL")))) -> 5 | G6: =IF(score_l_equations!G6="A",5,IF(score_l_equations!G6="B",4,IF(score_l_equations!G6="C",3,IF(score_l_equations!G6="D",1,"NULL")))) -> 4 | H6: =IF(score_l_equations!H6="A",5,IF(score_l_equations!H6="B",4,IF(score_l_equations!H6="C",3,IF(score_l_equations!H6="D",1,"NULL")))) -> 5 | I6: =IF(E6="Null","NULL",(SQRT(SQRT(E6*F6)*(AVERAGE(G6:H6))))) -> 4.7434165 | J6: =IF(score_l_equations!J6="A",5,IF(score_l_equations!J6="B",4,IF(score_l_equations!J6="B",4,IF(score_l_equations!J6="C",3,IF(score_l_equations!J6="C-",2,IF(score_l_equations!J6="D",1,"NULL")))))) -> 3 | K6: =IF(score_l_equations!K6="A",5,IF(score_l_equations!K6="B",4,IF(score_l_equations!K6="B",4,IF(score_l_equations!K6="C",3,IF(score_l_equations!K6="C-",2,IF(score_l_equations!K6="D",1,"NULL")))))) -> 4 | L6: =IF(score_l_equations!L6="A",5,IF(score_l_equations!L6="B",4,IF(score_l_equations!L6="B",4,IF(score_l_equations!L6="C",3,IF(score_l_equations!L6="C-",2,IF(score_l_equations!L6="D",1,"NULL")))))) -> 4 | M6: =IF(score_l_equations!M6="A",5,IF(score_l_equations!M6="B",4,IF(score_l_equations!M6="B",4,IF(score_l_equations!M6="C",3,IF(score_l_equations!M6="C-",2,IF(score_l_equations!M6="D",1,"NULL")))))) -> 5 | N6: =IF(score_l_equations!N6="A",5,IF(score_l_equations!N6="B",4,IF(score_l_equations!N6="B",4,IF(score_l_equations!N6="C",3,IF(score_l_equations!N6="C-",2,IF(score_l_equations!N6="D",1,"NULL")))))) -> NULL | O6: =IF(score_l_equations!O6="A",5,IF(score_l_equations!O6="B",4,IF(score_l_equations!O6="B",4,IF(score_l_equations!O6="C",3,IF(score_l_equations!O6="C-",2,IF(score_l_equations!O6="D",1,"NULL")))))) -> NULL | P6: =IF(J6="Null","NULL",AVERAGE(J6:O6)) -> 4 | Q6: =IF(score_l_equations!Q6="A",5,IF(score_l_equations!Q6="B",4,IF(score_l_equations!Q6="C",3,IF(score_l_equations!Q6="D",1,"NULL")))) -> 5 | R6: =IF(score_l_equations!R6="A",5,IF(score_l_equations!R6="B",4,IF(score_l_equations!R6="C",3,IF(score_l_equations!R6="D",1,"NULL")))) -> 5 | S6: =IF(score_l_equations!S6="A",5,IF(score_l_equations!S6="B",4,IF(score_l_equations!S6="C",3,IF(score_l_equations!S6="D",1,"NULL")))) -> 5 | T6: =IF(Q6="Null","NULL",AVERAGE(Q6:S6)) -> 5 | U6: =IF(score_l_equations!U6="A",5,IF(score_l_equations!U6="B",4,IF(score_l_equations!U6="C",3,IF(score_l_equations!U6="D",1,"NULL")))) -> 4 | V6: =IF(score_l_equations!V6="A",5,IF(score_l_equations!V6="B",4,IF(score_l_equations!V6="C",3,IF(score_l_equations!V6="D",1,"NULL")))) -> 5 | W6: =IF(score_l_equations!W6="A",5,IF(score_l_equations!W6="B",4,IF(score_l_equations!W6="C",3,IF(score_l_equations!W6="D",1,"NULL")))) -> 5 | X6: =IF(U6="Null","NULL",AVERAGE(U6:W6)) -> 4.6666667 | Y6: =IF(score_l_equations!Y6="A",5,IF(score_l_equations!Y6="B",4,IF(score_l_equations!Y6="C",3,IF(score_l_equations!Y6="D",1,"NULL")))) -> 4 | Z6: =IF(score_l_equations!Z6="A",5,IF(score_l_equations!Z6="B",4,IF(score_l_equations!Z6="C",3,IF(score_l_equations!Z6="D",1,"NULL")))) -> 5 | AA6: =IF(Y6="Null","NULL",AVERAGE(Y6:Z6)) -> 4.5 | AB6: =(D6*0.33)+(I6*0.67) -> 4.828089 | AC6: =(P6*0.55)+(T6*0.35)+(X6*0.1) -> 4.4166667 | AD6: =(AB6*0.3)+(AC6*0.7) -> 4.5400934 | AE6: =AD6+AF6 -> 5.0400934 | AF6: =IF(AA6<1.5,-0.5,IF(AA6<2.5,-0.25,IF(AA6<3.5,0.25,0.5))) -> 0.5
A7: 1102 | B7: =IF(score_l_equations!B7="A",5,IF(score_l_equations!B7="B",4,IF(score_l_equations!B7="C",3,IF(score_l_equations!B7="D",1,"NULL")))) -> 4 | C7: =IF(score_l_equations!C7="A",5,IF(score_l_equations!C7="B",4,IF(score_l_equations!C7="C",3,IF(score_l_equations!C7="D",1,"NULL")))) -> 5 | D7: =IF(B7="Null","NULL",AVERAGE(B7:C7)) -> 4.5 | E7: =IF(score_l_equations!E7="A",5,IF(score_l_equations!E7="B",4,IF(score_l_equations!E7="C",3,IF(score_l_equations!E7="D",1,"NULL")))) -> 4 | F7: =IF(score_l_equations!F7="A",5,IF(score_l_equations!F7="B",4,IF(score_l_equations!F7="C",3,IF(score_l_equations!F7="D",1,"NULL")))) -> 4 | G7: =IF(score_l_equations!G7="A",5,IF(score_l_equations!G7="B",4,IF(score_l_equations!G7="C",3,IF(score_l_equations!G7="D",1,"NULL")))) -> 5 | H7: =IF(score_l_equations!H7="A",5,IF(score_l_equations!H7="B",4,IF(score_l_equations!H7="C",3,IF(score_l_equations!H7="D",1,"NULL")))) -> 5 | I7: =IF(E7="Null","NULL",(SQRT(SQRT(E7*F7)*(AVERAGE(G7:H7))))) -> 4.472136 | J7: =IF(score_l_equations!J7="A",5,IF(score_l_equations!J7="B",4,IF(score_l_equations!J7="B",4,IF(score_l_equations!J7="C",3,IF(score_l_equations!J7="C-",2,IF(score_l_equations!J7="D",1,"NULL")))))) -> 3 | K7: =IF(score_l_equations!K7="A",5,IF(score_l_equations!K7="B",4,IF(score_l_equations!K7="B",4,IF(score_l_equations!K7="C",3,IF(score_l_equations!K7="C-",2,IF(score_l_equations!K7="D",1,"NULL")))))) -> 5 | L7: =IF(score_l_equations!L7="A",5,IF(score_l_equations!L7="B",4,IF(score_l_equations!L7="B",4,IF(score_l_equations!L7="C",3,IF(score_l_equations!L7="C-",2,IF(score_l_equations!L7="D",1,"NULL")))))) -> 5 | M7: =IF(score_l_equations!M7="A",5,IF(score_l_equations!M7="B",4,IF(score_l_equations!M7="B",4,IF(score_l_equations!M7="C",3,IF(score_l_equations!M7="C-",2,IF(score_l_equations!M7="D",1,"NULL")))))) -> 5 | N7: =IF(score_l_equations!N7="A",5,IF(score_l_equations!N7="B",4,IF(score_l_equations!N7="B",4,IF(score_l_equations!N7="C",3,IF(score_l_equations!N7="C-",2,IF(score_l_equations!N7="D",1,"NULL")))))) -> NULL | O7: =IF(score_l_equations!O7="A",5,IF(score_l_equations!O7="B",4,IF(score_l_equations!O7="B",4,IF(score_l_equations!O7="C",3,IF(score_l_equations!O7="C-",2,IF(score_l_equations!O7="D",1,"NULL")))))) -> NULL | P7: =IF(J7="Null","NULL",AVERAGE(J7:O7)) -> 4.5 | Q7: =IF(score_l_equations!Q7="A",5,IF(score_l_equations!Q7="B",4,IF(score_l_equations!Q7="C",3,IF(score_l_equations!Q7="D",1,"NULL")))) -> 5 | R7: =IF(score_l_equations!R7="A",5,IF(score_l_equations!R7="B",4,IF(score_l_equations!R7="C",3,IF(score_l_equations!R7="D",1,"NULL")))) -> 5 | S7: =IF(score_l_equations!S7="A",5,IF(score_l_equations!S7="B",4,IF(score_l_equations!S7="C",3,IF(score_l_equations!S7="D",1,"NULL")))) -> 5 | T7: =IF(Q7="Null","NULL",AVERAGE(Q7:S7)) -> 5 | U7: =IF(score_l_equations!U7="A",5,IF(score_l_equations!U7="B",4,IF(score_l_equations!U7="C",3,IF(score_l_equations!U7="D",1,"NULL")))) -> 5 | V7: =IF(score_l_equations!V7="A",5,IF(score_l_equations!V7="B",4,IF(score_l_equations!V7="C",3,IF(score_l_equations!V7="D",1,"NULL")))) -> 5 | W7: =IF(score_l_equations!W7="A",5,IF(score_l_equations!W7="B",4,IF(score_l_equations!W7="C",3,IF(score_l_equations!W7="D",1,"NULL")))) -> 5 | X7: =IF(U7="Null","NULL",AVERAGE(U7:W7)) -> 5 | Y7: =IF(score_l_equations!Y7="A",5,IF(score_l_equations!Y7="B",4,IF(score_l_equations!Y7="C",3,IF(score_l_equations!Y7="D",1,"NULL")))) -> 5 | Z7: =IF(score_l_equations!Z7="A",5,IF(score_l_equations!Z7="B",4,IF(score_l_equations!Z7="C",3,IF(score_l_equations!Z7="D",1,"NULL")))) -> 3 | AA7: =IF(Y7="Null","NULL",AVERAGE(Y7:Z7)) -> 4 | AB7: =(D7*0.33)+(I7*0.67) -> 4.4813311 | AC7: =(P7*0.55)+(T7*0.35)+(X7*0.1) -> 4.725 | AD7: =(AB7*0.3)+(AC7*0.7) -> 4.6518993 | AE7: =AD7+AF7 -> 5.1518993 | AF7: =IF(AA7<1.5,-0.5,IF(AA7<2.5,-0.25,IF(AA7<3.5,0.25,0.5))) -> 0.5
A8: 1251 | B8: =IF(score_l_equations!B8="A",5,IF(score_l_equations!B8="B",4,IF(score_l_equations!B8="C",3,IF(score_l_equations!B8="D",1,"NULL")))) -> 5 | C8: =IF(score_l_equations!C8="A",5,IF(score_l_equations!C8="B",4,IF(score_l_equations!C8="C",3,IF(score_l_equations!C8="D",1,"NULL")))) -> 5 | D8: =IF(B8="Null","NULL",AVERAGE(B8:C8)) -> 5 | E8: =IF(score_l_equations!E8="A",5,IF(score_l_equations!E8="B",4,IF(score_l_equations!E8="C",3,IF(score_l_equations!E8="D",1,"NULL")))) -> 5 | F8: =IF(score_l_equations!F8="A",5,IF(score_l_equations!F8="B",4,IF(score_l_equations!F8="C",3,IF(score_l_equations!F8="D",1,"NULL")))) -> 5 | G8: =IF(score_l_equations!G8="A",5,IF(score_l_equations!G8="B",4,IF(score_l_equations!G8="C",3,IF(score_l_equations!G8="D",1,"NULL")))) -> 5 | H8: =IF(score_l_equations!H8="A",5,IF(score_l_equations!H8="B",4,IF(score_l_equations!H8="C",3,IF(score_l_equations!H8="D",1,"NULL")))) -> 5 | I8: =IF(E8="Null","NULL",(SQRT(SQRT(E8*F8)*(AVERAGE(G8:H8))))) -> 5 | J8: =IF(score_l_equations!J8="A",5,IF(score_l_equations!J8="B",4,IF(score_l_equations!J8="B",4,IF(score_l_equations!J8="C",3,IF(score_l_equations!J8="C-",2,IF(score_l_equations!J8="D",1,"NULL")))))) -> 3 | K8: =IF(score_l_equations!K8="A",5,IF(score_l_equations!K8="B",4,IF(score_l_equations!K8="B",4,IF(score_l_equations!K8="C",3,IF(score_l_equations!K8="C-",2,IF(score_l_equations!K8="D",1,"NULL")))))) -> 3 | L8: =IF(score_l_equations!L8="A",5,IF(score_l_equations!L8="B",4,IF(score_l_equations!L8="B",4,IF(score_l_equations!L8="C",3,IF(score_l_equations!L8="C-",2,IF(score_l_equations!L8="D",1,"NULL")))))) -> 3 | M8: =IF(score_l_equations!M8="A",5,IF(score_l_equations!M8="B",4,IF(score_l_equations!M8="B",4,IF(score_l_equations!M8="C",3,IF(score_l_equations!M8="C-",2,IF(score_l_equations!M8="D",1,"NULL")))))) -> 3 | N8: =IF(score_l_equations!N8="A",5,IF(score_l_equations!N8="B",4,IF(score_l_equations!N8="B",4,IF(score_l_equations!N8="C",3,IF(score_l_equations!N8="C-",2,IF(score_l_equations!N8="D",1,"NULL")))))) -> NULL | O8: =IF(score_l_equations!O8="A",5,IF(score_l_equations!O8="B",4,IF(score_l_equations!O8="B",4,IF(score_l_equations!O8="C",3,IF(score_l_equations!O8="C-",2,IF(score_l_equations!O8="D",1,"NULL")))))) -> NULL | P8: =IF(J8="Null","NULL",AVERAGE(J8:O8)) -> 3 | Q8: =IF(score_l_equations!Q8="A",5,IF(score_l_equations!Q8="B",4,IF(score_l_equations!Q8="C",3,IF(score_l_equations!Q8="D",1,"NULL")))) -> 5 | R8: =IF(score_l_equations!R8="A",5,IF(score_l_equations!R8="B",4,IF(score_l_equations!R8="C",3,IF(score_l_equations!R8="D",1,"NULL")))) -> 5 | S8: =IF(score_l_equations!S8="A",5,IF(score_l_equations!S8="B",4,IF(score_l_equations!S8="C",3,IF(score_l_equations!S8="D",1,"NULL")))) -> 4 | T8: =IF(Q8="Null","NULL",AVERAGE(Q8:S8)) -> 4.6666667 | U8: =IF(score_l_equations!U8="A",5,IF(score_l_equations!U8="B",4,IF(score_l_equations!U8="C",3,IF(score_l_equations!U8="D",1,"NULL")))) -> 3 | V8: =IF(score_l_equations!V8="A",5,IF(score_l_equations!V8="B",4,IF(score_l_equations!V8="C",3,IF(score_l_equations!V8="D",1,"NULL")))) -> 5 | W8: =IF(score_l_equations!W8="A",5,IF(score_l_equations!W8="B",4,IF(score_l_equations!W8="C",3,IF(score_l_equations!W8="D",1,"NULL")))) -> 3 | X8: =IF(U8="Null","NULL",AVERAGE(U8:W8)) -> 3.6666667 | Y8: =IF(score_l_equations!Y8="A",5,IF(score_l_equations!Y8="B",4,IF(score_l_equations!Y8="C",3,IF(score_l_equations!Y8="D",1,"NULL")))) -> 4 | Z8: =IF(score_l_equations!Z8="A",5,IF(score_l_equations!Z8="B",4,IF(score_l_equations!Z8="C",3,IF(score_l_equations!Z8="D",1,"NULL")))) -> 5 | AA8: =IF(Y8="Null","NULL",AVERAGE(Y8:Z8)) -> 4.5 | AB8: =(D8*0.33)+(I8*0.67) -> 5 | AC8: =(P8*0.55)+(T8*0.35)+(X8*0.1) -> 3.65 | AD8: =(AB8*0.3)+(AC8*0.7) -> 4.055 | AE8: =AD8+AF8 -> 4.555 | AF8: =IF(AA8<1.5,-0.5,IF(AA8<2.5,-0.25,IF(AA8<3.5,0.25,0.5))) -> 0.5
A9: 1270 | B9: =IF(score_l_equations!B9="A",5,IF(score_l_equations!B9="B",4,IF(score_l_equations!B9="C",3,IF(score_l_equations!B9="D",1,"NULL")))) -> 4 | C9: =IF(score_l_equations!C9="A",5,IF(score_l_equations!C9="B",4,IF(score_l_equations!C9="C",3,IF(score_l_equations!C9="D",1,"NULL")))) -> 5 | D9: =IF(B9="Null","NULL",AVERAGE(B9:C9)) -> 4.5 | E9: =IF(score_l_equations!E9="A",5,IF(score_l_equations!E9="B",4,IF(score_l_equations!E9="C",3,IF(score_l_equations!E9="D",1,"NULL")))) -> 5 | F9: =IF(score_l_equations!F9="A",5,IF(score_l_equations!F9="B",4,IF(score_l_equations!F9="C",3,IF(score_l_equations!F9="D",1,"NULL")))) -> 5 | G9: =IF(score_l_equations!G9="A",5,IF(score_l_equations!G9="B",4,IF(score_l_equations!G9="C",3,IF(score_l_equations!G9="D",1,"NULL")))) -> 3 | H9: =IF(score_l_equations!H9="A",5,IF(score_l_equations!H9="B",4,IF(score_l_equations!H9="C",3,IF(score_l_equations!H9="D",1,"NULL")))) -> 4 | I9: =IF(E9="Null","NULL",(SQRT(SQRT(E9*F9)*(AVERAGE(G9:H9))))) -> 4.1833001 | J9: =IF(score_l_equations!J9="A",5,IF(score_l_equations!J9="B",4,IF(score_l_equations!J9="B",4,IF(score_l_equations!J9="C",3,IF(score_l_equations!J9="C-",2,IF(score_l_equations!J9="D",1,"NULL")))))) -> 2 | K9: =IF(score_l_equations!K9="A",5,IF(score_l_equations!K9="B",4,IF(score_l_equations!K9="B",4,IF(score_l_equations!K9="C",3,IF(score_l_equations!K9="C-",2,IF(score_l_equations!K9="D",1,"NULL")))))) -> 4 | L9: =IF(score_l_equations!L9="A",5,IF(score_l_equations!L9="B",4,IF(score_l_equations!L9="B",4,IF(score_l_equations!L9="C",3,IF(score_l_equations!L9="C-",2,IF(score_l_equations!L9="D",1,"NULL")))))) -> 3 | M9: =IF(score_l_equations!M9="A",5,IF(score_l_equations!M9="B",4,IF(score_l_equations!M9="B",4,IF(score_l_equations!M9="C",3,IF(score_l_equations!M9="C-",2,IF(score_l_equations!M9="D",1,"NULL")))))) -> 3 | N9: =IF(score_l_equations!N9="A",5,IF(score_l_equations!N9="B",4,IF(score_l_equations!N9="B",4,IF(score_l_equations!N9="C",3,IF(score_l_equations!N9="C-",2,IF(score_l_equations!N9="D",1,"NULL")))))) -> NULL | O9: =IF(score_l_equations!O9="A",5,IF(score_l_equations!O9="B",4,IF(score_l_equations!O9="B",4,IF(score_l_equations!O9="C",3,IF(score_l_equations!O9="C-",2,IF(score_l_equations!O9="D",1,"NULL")))))) -> NULL | P9: =IF(J9="Null","NULL",AVERAGE(J9:O9)) -> 3 | Q9: =IF(score_l_equations!Q9="A",5,IF(score_l_equations!Q9="B",4,IF(score_l_equations!Q9="C",3,IF(score_l_equations!Q9="D",1,"NULL")))) -> 5 | R9: =IF(score_l_equations!R9="A",5,IF(score_l_equations!R9="B",4,IF(score_l_equations!R9="C",3,IF(score_l_equations!R9="D",1,"NULL")))) -> 5 | S9: =IF(score_l_equations!S9="A",5,IF(score_l_equations!S9="B",4,IF(score_l_equations!S9="C",3,IF(score_l_equations!S9="D",1,"NULL")))) -> 5 | T9: =IF(Q9="Null","NULL",AVERAGE(Q9:S9)) -> 5 | U9: =IF(score_l_equations!U9="A",5,IF(score_l_equations!U9="B",4,IF(score_l_equations!U9="C",3,IF(score_l_equations!U9="D",1,"NULL")))) -> 5 | V9: =IF(score_l_equations!V9="A",5,IF(score_l_equations!V9="B",4,IF(score_l_equations!V9="C",3,IF(score_l_equations!V9="D",1,"NULL")))) -> 5 | W9: =IF(score_l_equations!W9="A",5,IF(score_l_equations!W9="B",4,IF(score_l_equations!W9="C",3,IF(score_l_equations!W9="D",1,"NULL")))) -> 3 | X9: =IF(U9="Null","NULL",AVERAGE(U9:W9)) -> 4.3333333 | Y9: =IF(score_l_equations!Y9="A",5,IF(score_l_equations!Y9="B",4,IF(score_l_equations!Y9="C",3,IF(score_l_equations!Y9="D",1,"NULL")))) -> 5 | Z9: =IF(score_l_equations!Z9="A",5,IF(score_l_equations!Z9="B",4,IF(score_l_equations!Z9="C",3,IF(score_l_equations!Z9="D",1,"NULL")))) -> 5 | AA9: =IF(Y9="Null","NULL",AVERAGE(Y9:Z9)) -> 5 | AB9: =(D9*0.33)+(I9*0.67) -> 4.2878111 | AC9: =(P9*0.55)+(T9*0.35)+(X9*0.1) -> 3.8333333 | AD9: =(AB9*0.3)+(AC9*0.7) -> 3.9696767 | AE9: =AD9+AF9 -> 4.4696767 | AF9: =IF(AA9<1.5,-0.5,IF(AA9<2.5,-0.25,IF(AA9<3.5,0.25,0.5))) -> 0.5
A10: 1368 | B10: =IF(score_l_equations!B10="A",5,IF(score_l_equations!B10="B",4,IF(score_l_equations!B10="C",3,IF(score_l_equations!B10="D",1,"NULL")))) -> 5 | C10: =IF(score_l_equations!C10="A",5,IF(score_l_equations!C10="B",4,IF(score_l_equations!C10="C",3,IF(score_l_equations!C10="D",1,"NULL")))) -> 5 | D10: =IF(B10="Null","NULL",AVERAGE(B10:C10)) -> 5 | E10: =IF(score_l_equations!E10="A",5,IF(score_l_equations!E10="B",4,IF(score_l_equations!E10="C",3,IF(score_l_equations!E10="D",1,"NULL")))) -> 5 | F10: =IF(score_l_equations!F10="A",5,IF(score_l_equations!F10="B",4,IF(score_l_equations!F10="C",3,IF(score_l_equations!F10="D",1,"NULL")))) -> 5 | G10: =IF(score_l_equations!G10="A",5,IF(score_l_equations!G10="B",4,IF(score_l_equations!G10="C",3,IF(score_l_equations!G10="D",1,"NULL")))) -> 4 | H10: =IF(score_l_equations!H10="A",5,IF(score_l_equations!H10="B",4,IF(score_l_equations!H10="C",3,IF(score_l_equations!H10="D",1,"NULL")))) -> 4 | I10: =IF(E10="Null","NULL",(SQRT(SQRT(E10*F10)*(AVERAGE(G10:H10))))) -> 4.472136 | J10: =IF(score_l_equations!J10="A",5,IF(score_l_equations!J10="B",4,IF(score_l_equations!J10="B",4,IF(score_l_equations!J10="C",3,IF(score_l_equations!J10="C-",2,IF(score_l_equations!J10="D",1,"NULL")))))) -> 4 | K10: =IF(score_l_equations!K10="A",5,IF(score_l_equations!K10="B",4,IF(score_l_equations!K10="B",4,IF(score_l_equations!K10="C",3,IF(score_l_equations!K10="C-",2,IF(score_l_equations!K10="D",1,"NULL")))))) -> 4 | L10: =IF(score_l_equations!L10="A",5,IF(score_l_equations!L10="B",4,IF(score_l_equations!L10="B",4,IF(score_l_equations!L10="C",3,IF(score_l_equations!L10="C-",2,IF(score_l_equations!L10="D",1,"NULL")))))) -> 5 | M10: =IF(score_l_equations!M10="A",5,IF(score_l_equations!M10="B",4,IF(score_l_equations!M10="B",4,IF(score_l_equations!M10="C",3,IF(score_l_equations!M10="C-",2,IF(score_l_equations!M10="D",1,"NULL")))))) -> 5 | N10: =IF(score_l_equations!N10="A",5,IF(score_l_equations!N10="B",4,IF(score_l_equations!N10="B",4,IF(score_l_equations!N10="C",3,IF(score_l_equations!N10="C-",2,IF(score_l_equations!N10="D",1,"NULL")))))) -> NULL | O10: =IF(score_l_equations!O10="A",5,IF(score_l_equations!O10="B",4,IF(score_l_equations!O10="B",4,IF(score_l_equations!O10="C",3,IF(score_l_equations!O10="C-",2,IF(score_l_equations!O10="D",1,"NULL")))))) -> NULL | P10: =IF(J10="Null","NULL",AVERAGE(J10:O10)) -> 4.5 | Q10: =IF(score_l_equations!Q10="A",5,IF(score_l_equations!Q10="B",4,IF(score_l_equations!Q10="C",3,IF(score_l_equations!Q10="D",1,"NULL")))) -> 5 | R10: =IF(score_l_equations!R10="A",5,IF(score_l_equations!R10="B",4,IF(score_l_equations!R10="C",3,IF(score_l_equations!R10="D",1,"NULL")))) -> 4 | S10: =IF(score_l_equations!S10="A",5,IF(score_l_equations!S10="B",4,IF(score_l_equations!S10="C",3,IF(score_l_equations!S10="D",1,"NULL")))) -> 4 | T10: =IF(Q10="Null","NULL",AVERAGE(Q10:S10)) -> 4.3333333 | U10: =IF(score_l_equations!U10="A",5,IF(score_l_equations!U10="B",4,IF(score_l_equations!U10="C",3,IF(score_l_equations!U10="D",1,"NULL")))) -> 3 | V10: =IF(score_l_equations!V10="A",5,IF(score_l_equations!V10="B",4,IF(score_l_equations!V10="C",3,IF(score_l_equations!V10="D",1,"NULL")))) -> 5 | W10: =IF(score_l_equations!W10="A",5,IF(score_l_equations!W10="B",4,IF(score_l_equations!W10="C",3,IF(score_l_equations!W10="D",1,"NULL")))) -> 5 | X10: =IF(U10="Null","NULL",AVERAGE(U10:W10)) -> 4.3333333 | Y10: =IF(score_l_equations!Y10="A",5,IF(score_l_equations!Y10="B",4,IF(score_l_equations!Y10="C",3,IF(score_l_equations!Y10="D",1,"NULL")))) -> 5 | Z10: =IF(score_l_equations!Z10="A",5,IF(score_l_equations!Z10="B",4,IF(score_l_equations!Z10="C",3,IF(score_l_equations!Z10="D",1,"NULL")))) -> 5 | AA10: =IF(Y10="Null","NULL",AVERAGE(Y10:Z10)) -> 5 | AB10: =(D10*0.33)+(I10*0.67) -> 4.6463311 | AC10: =(P10*0.55)+(T10*0.35)+(X10*0.1) -> 4.425 | AD10: =(AB10*0.3)+(AC10*0.7) -> 4.4913993 | AE10: =AD10+AF10 -> 4.9913993 | AF10: =IF(AA10<1.5,-0.5,IF(AA10<2.5,-0.25,IF(AA10<3.5,0.25,0.5))) -> 0.5
